ERROR:root:
Traceback (most recent call last):
  File "scrap.py", line 4, in <module>
    raise Exception
Exception
